<?xml version="1.0"?>
<robot name="tinykart">

<!-- Base footprint -->
    <link name="base_footprint"/>
    
<!--Chassis link and joint -->    
    <link name="base_link">
        <visual>
            <origin rpy="0 0 0" xyz="0 0 0" />
            <geometry>
                <box size="0.55245 0.19 0.02"/>
            </geometry>
        </visual>
        <collision>
            <origin rpy="0 0 0" xyz="0 0 0" />
            <geometry>
                <box size="0.55245 0.19 0.02"/>
            </geometry>
        </collision>
        <inertial>
            <origin xyz="0 0 0" rpy="0 0 0"/>
            <mass value="1"/>
            <inertia
                ixx="0.000315771" ixy="0.0" ixz="0.0"
                iyy="0.00266963" iyz="0.0"
                izz="0.0"/>
        </inertial>
    </link>
    
    <joint name="base_footprint_to_base_link" type="fixed">
        <origin rpy="0 0 0" xyz="0 0 0.09525"/>
        <parent link="base_footprint"/>
        <child link="base_link"/>
    </joint>
    
    
<!-- Wheel links and joints -->
    
    <!-- Left wheel link and joint -->
    <link name="left_front_wheel">
        <visual>
            <origin rpy="1.5708 0 0" xyz="0 0 0" />
            <geometry>
                <cylinder length="0.04" radius="0.05"/>
            </geometry>
        </visual>
        <collision>
            <origin rpy="1.5708 0 0" xyz="0 0 0" />
            <geometry>
                <cylinder length="0.04" radius="0.05"/>
            </geometry>
        </collision>
        <inertial>
            <origin xyz="0 0 0" rpy="1.5708 0 0"/>
            <mass value="0.1"/>
            <inertia
                ixx="7.6E-05" ixy="0.0" ixz="0.0"
                iyy="7.6E-05" iyz="0.0"
                izz="0.000125"/>
        </inertial>
    </link>

    <!-- The joint where the left wheel pivots about -->
    <link name="left_front_wheel_rack">
    <!-- These visuals are needed, else gazebo crashes -->
    <visual>
            <origin rpy="1.5708 0 0" xyz="0 0 0" />
            <geometry>
                <box size="0.00001 0.0000001 0.000001"/>
            </geometry>
        </visual>
        <inertial>
            <origin xyz="0 0 0" rpy="1.5708 0 0"/>
            <mass value="0.001"/>
            <inertia
                ixx="7.6E-07" ixy="0.0" ixz="0.0"
                iyy="7.6E-07" iyz="0.0"
                izz="0.000001"/>
        </inertial>
    </link>

    <joint name="left_front_wheel_steer" type="revolute">
        <origin rpy="0 0 0" xyz="0.219075 0.095 -0.054"/>
        <parent link="base_link"/>
        <child link="left_front_wheel_rack"/>
        <axis xyz="0 0 1"/>
        <limit lower="-0.3499" upper="+0.5236" velocity="3.0" effort="0.88269"/>
    </joint>
    
    <joint name="left_front_wheel_rack_to_wheel" type="continuous">
        <origin rpy="0 0 0" xyz="0 -0.00001 0"/>
        <parent link="left_front_wheel_rack"/>
        <child link="left_front_wheel"/>
        <axis xyz="0 1 0"/>
    </joint>
    
    <!-- Right wheel link and joint -->
    <link name="right_front_wheel">
        <visual>
            <origin rpy="1.5708 0 0" xyz="0 0 0" />
            <geometry>
               <cylinder length="0.04" radius="0.05"/>
            </geometry>
        </visual>
        <collision>
            <origin rpy="1.5708 0 0" xyz="0 0 0" />
            <geometry>
                <cylinder length="0.04" radius="0.05"/>
            </geometry>
        </collision>
        <inertial>
            <origin xyz="0 0 0" rpy="1.5708 0 0"/>
            <mass value="0.1"/>
            <inertia
                ixx="7.6E-05" ixy="0.0" ixz="0.0"
                iyy="7.6E-05" iyz="0.0"
                izz="0.000125"/>
        </inertial>
    </link>

    <!-- The joint where the right wheel pivots about -->
    <link name="right_front_wheel_rack">
    <!-- These visuals are needed, else gazebo crashes -->
    <visual>
            <origin rpy="1.5708 0 0" xyz="0 0 0" />
            <geometry>
                <box size="0.00001 0.0000001 0.000001"/>
            </geometry>
        </visual>
        <inertial>
            <origin xyz="0 0 0" rpy="1.5708 0 0"/>
            <mass value="0.001"/>
            <inertia
                ixx="7.6E-07" ixy="0.0" ixz="0.0"
                iyy="7.6E-07" iyz="0.0"
                izz="0.000001"/>
        </inertial>
    </link>
    
    <joint name="right_front_wheel_steer" type="revolute">
        <origin rpy="0 0 0" xyz=" 0.219075 -0.095 -0.054"/>
        <parent link="base_link"/>
        <child link="right_front_wheel_rack"/>
        <axis xyz="0 0 1"/>
        <limit lower="-0.3499" upper="+0.5236" velocity="3.0" effort="0.88269"/>
    </joint> 
    
    <joint name="right_front_wheel_rack_to_wheel" type="continuous">
        <origin rpy="0 0 0" xyz="0 -0.00001 0"/>
        <parent link="right_front_wheel_rack"/>
        <child link="right_front_wheel"/>
        <axis xyz="0 1 0"/>
    </joint> 
    
    <!-- Right rear wheel link and joint -->
    <link name="right_rear_wheel">
        <visual>
            <origin rpy="1.5708 0 0" xyz="0 0 0" />
            <geometry>
                <cylinder length="0.04" radius="0.05"/>
            </geometry>
        </visual>
        <collision>
            <origin rpy="1.5708 0 0" xyz="0 0 0" />
            <geometry>
                <cylinder length="0.04" radius="0.05"/>
            </geometry>
        </collision>
        <inertial>
            <origin xyz="0 0 0" rpy="1.5708 0 0"/>
            <mass value="0.1"/>
            <inertia
                ixx="7.6E-05" ixy="0.0" ixz="0.0"
                iyy="7.6E-05" iyz="0.0"
                izz="0.000125"/>
        </inertial>
    </link>
    
    <joint name="right_rear_wheel_to_base_link" type="continuous">
        <origin rpy="0 0 0" xyz="-0.140575 -0.095 -0.054"/>
        <parent link="base_link"/>
        <child link="right_rear_wheel"/>
        <axis xyz="0 1 0"/>
    </joint>
    
    <!-- Left rear wheel link and joint -->
    <link name="left_rear_wheel">
        <visual>
            <origin rpy="1.5708 0 0" xyz="0 0 0" />
            <geometry>
                <cylinder length="0.04" radius="0.05"/>
            </geometry>
        </visual>
        <collision>
            <origin rpy="1.5708 0 0" xyz="0 0 0" />
            <geometry>
                <cylinder length="0.04" radius="0.05"/>
            </geometry>
        </collision>
        <inertial>
            <origin xyz="0 0 0" rpy="1.5708 0 0"/>
            <mass value="0.1"/>
            <inertia
                ixx="7.6E-05" ixy="0.0" ixz="0.0"
                iyy="7.6E-05" iyz="0.0"
                izz="0.000125"/>
        </inertial>
    </link>
    
    <joint name="left_rear_wheel_to_base_link" type="continuous">
        <origin rpy="0 0 0" xyz="-0.140575 0.095 -0.054"/>
        <parent link="base_link"/>
        <child link="left_rear_wheel"/>
        <axis xyz="0 1 0"/>
    </joint>
    
<!-- Sensors -->

    <!-- Lidar Link and joint -->
    <link name="laser_link">
        <visual>
            <origin rpy="0 0 0" xyz="0 0 0" />
            <geometry>
                <cylinder length="0.01" radius="0.00762"/>
            </geometry>
        </visual>
        <collision>
            <origin rpy="0 0 0" xyz="0 0 0" />
            <geometry>
                <cylinder length="0.01" radius="0.00762"/>
            </geometry>
        </collision>
        <inertial>
            <origin xyz="0 0 0" rpy="0 0 0"/>
            <mass value="0"/>
            <inertia
                ixx="5.4e-05" ixy="0.0" ixz="0.0"
                iyy="5.4e-05" iyz="0.0"
                izz="0.002903"/>
        </inertial>
    </link>
    
    <joint name="laser_to_base_link" type="fixed">
        <origin rpy="0 0 0" xyz="0.2722 0 0.2"/>
        <parent link="base_link"/>
        <child link="laser_link"/>
    </joint>
    
    
  <!-- Imu link, joint, and sensor component -->
    <link name="imu_link">
        <visual>
            <origin rpy="0 0 0" xyz="0 0 0" />
            <geometry>
                <box size="0.0254 0.0254 0.0254"/>
            </geometry>
        </visual>
        <collision>
            <origin rpy="0 0 0" xyz="0 0 0" />
            <geometry>
                <box size="0.0254 0.0254 0.0254"/>
            </geometry>
        </collision>
        <inertial>
            <origin xyz="0 0 0" rpy="0 0 0"/>
            <mass value="0"/>
            <inertia
                ixx="5.4e-05" ixy="0.0" ixz="0.0"
                iyy="5.4e-05" iyz="0.0"
                izz="0.000108"/>
        </inertial>
    </link>
    
    <joint name="imu_link_to_base_link" type="fixed">
        <origin rpy="0 0 0" xyz="-0.012 0 0.3"/>
        <parent link="base_link"/>
        <child link="imu_link"/>
    </joint>
    
</robot>
            
