<?xml version="1.0"?>
<robot name="tinykart">

<!-- Base footprint -->
    <link name="base_footprint">
    	<visual>
    		<origin rpy="0 0 0" xyz="-0.285 0 0"/>
    	</visual>
    	<collision>
    		<origin rpy="0 0 0" xyz="-0.285 0 0"/>
    	</collision>
    </link>
    
<!--Chassis link and joint -->    
    <link name="base_link">
        <visual>
            <origin rpy="0 0 0" xyz="0 0 0" />
            <geometry>
                <box size="0.9 0.44 0.254"/>
            </geometry>
        </visual>
        <collision>
            <origin rpy="0 0 0" xyz="0 0 0" />
            <geometry>
                <box size="0.9 0.44 0.254"/>
            </geometry>
        </collision>
        <inertial>
            <origin xyz="0 0 0" rpy="0 0 0"/>
            <mass value="28"/>
            <inertia
                ixx="0.451733" ixy="0.0" ixz="0.0"
                iyy="1.89" iyz="0.0"
                izz="2.341733"/>
        </inertial>
    </link>
    
    <joint name="base_footprint_to_base_link" type="fixed">
        <origin rpy="0 0 0" xyz="0.285 0 0.225"/>
        <parent link="base_footprint"/>
        <child link="base_link"/>
    </joint>
    
    
<!-- Wheel links and joints -->
    
    <!-- Left wheel link and joint -->
    <link name="left_front_wheel">
        <visual>
            <origin rpy="1.5708 0 0" xyz="0 0 0" />
            <geometry>
                <cylinder length="0.1" radius="0.165"/>
            </geometry>
        </visual>
        <collision>
            <origin rpy="1.5708 0 0" xyz="0 0 0" />
            <geometry>
                <cylinder length="0.1" radius="0.165"/>
            </geometry>
        </collision>
        <inertial>
            <origin xyz="0 0 0" rpy="1.5708 0 0"/>
            <mass value="2.25"/>
            <inertia
                ixx="0.017189" ixy="0.0" ixz="0.0"
                iyy="0.017189" iyz="0.0"
                izz="0.030628"/>
        </inertial>
    </link>
    
    <joint name="left_front_wheel_to_base_link" type="continuous">
        <origin rpy="0 0 0" xyz="0.285 0.27 -0.0508"/>
        <parent link="base_link"/>
        <child link="left_front_wheel"/>
        <axis xyz="0 1 0"/>
    </joint>
    
    <!-- Right wheel link and joint -->
    <link name="right_front_wheel">
        <visual>
            <origin rpy="1.5708 0 0" xyz="0 0 0" />
            <geometry>
                <cylinder length="0.1" radius="0.165"/>
            </geometry>
        </visual>
        <collision>
            <origin rpy="1.5708 0 0" xyz="0 0 0" />
            <geometry>
                <cylinder length="0.1" radius="0.165"/>
            </geometry>
        </collision>
        <inertial>
            <origin xyz="0 0 0" rpy="1.5708 0 0"/>
            <mass value="2.25"/>
            <inertia
                ixx="0.017189" ixy="0.0" ixz="0.0"
                iyy="0.017189" iyz="0.0"
                izz="0.030628"/>
        </inertial>
    </link>
    
    <joint name="right_front_wheel_to_base_link" type="continuous">
        <origin rpy="0 0 0" xyz="0.285 -0.27 -0.0508"/>
        <parent link="base_link"/>
        <child link="right_front_wheel"/>
        <axis xyz="0 1 0"/>
    </joint> 
    
    <!-- Right rear wheel link and joint -->
    <link name="right_rear_wheel">
        <visual>
            <origin rpy="1.5708 0 0" xyz="0 0 0" />
            <geometry>
                <cylinder length="0.1" radius="0.165"/>
            </geometry>
        </visual>
        <collision>
            <origin rpy="1.5708 0 0" xyz="0 0 0" />
            <geometry>
                <cylinder length="0.1" radius="0.165"/>
            </geometry>
        </collision>
        <inertial>
            <origin xyz="0 0 0" rpy="1.5708 0 0"/>
            <mass value="2.25"/>
            <inertia
                ixx="0.017189" ixy="0.0" ixz="0.0"
                iyy="0.017189" iyz="0.0"
                izz="0.030628"/>
        </inertial>
    </link>
    
    <joint name="right_rear_wheel_to_base_link" type="continuous">
        <origin rpy="0 0 0" xyz="-0.285 -0.27 -0.0508"/>
        <parent link="base_link"/>
        <child link="right_rear_wheel"/>
        <axis xyz="0 1 0"/>
    </joint>
    
    
    
    <!-- Left rear wheel link and joint -->
    <link name="left_rear_wheel">
        <visual>
            <origin rpy="1.5708 0 0" xyz="0 0 0" />
            <geometry>
                <cylinder length="0.1" radius="0.165"/>
            </geometry>
        </visual>
        <collision>
            <origin rpy="1.5708 0 0" xyz="0 0 0" />
            <geometry>
                <cylinder length="0.1" radius="0.165"/>
            </geometry>
        </collision>
        <inertial>
            <origin xyz="0 0 0" rpy="1.5708 0 0"/>
            <mass value="2.25"/>
            <inertia
                ixx="0.017189" ixy="0.0" ixz="0.0"
                iyy="0.017189" iyz="0.0"
                izz="0.030628"/>
        </inertial>
    </link>
    
    <joint name="left_rear_wheel_to_base_link" type="continuous">
        <origin rpy="0 0 0" xyz="-0.285 0.27 -0.0508"/>
        <parent link="base_link"/>
        <child link="left_rear_wheel"/>
        <axis xyz="0 1 0"/>
    </joint>
    
    <!-- Left mid wheel link and joint -->
    <link name="left_mid_wheel">
        <visual>
            <origin rpy="1.5708 0 0" xyz="0 0 0" />
            <geometry>
                <cylinder length="0.1" radius="0.165"/>
            </geometry>
        </visual>
        <collision>
            <origin rpy="1.5708 0 0" xyz="0 0 0" />
            <geometry>
                <cylinder length="0.1" radius="0.165"/>
            </geometry>
        </collision>
        <inertial>
            <origin xyz="0 0 0" rpy="1.5708 0 0"/>
            <mass value="2.25"/>
            <inertia
                ixx="0.017189" ixy="0.0" ixz="0.0"
                iyy="0.017189" iyz="0.0"
                izz="0.030628"/>
        </inertial>
    </link>
    
    <joint name="left_mid_wheel_to_base_link" type="continuous">
        <origin rpy="0 0 0" xyz="0 0.27 -0.0508"/>
        <parent link="base_link"/>
        <child link="left_mid_wheel"/>
        <axis xyz="0 1 0"/>
    </joint>    
    
    
    <!--Right mid wheel link and joint -->
    <link name="right_mid_wheel">
        <visual>
            <origin rpy="1.5708 0 0" xyz="0 0 0" />
            <geometry>
                <cylinder length="0.1" radius="0.165"/>
            </geometry>
        </visual>
        <collision>
            <origin rpy="1.5708 0 0" xyz="0 0 0" />
            <geometry>
                <cylinder length="0.1" radius="0.165"/>
            </geometry>
        </collision>
        <inertial>
            <origin xyz="0 0 0" rpy="1.5708 0 0"/>
            <mass value="2.25"/>
            <inertia
                ixx="0.017189" ixy="0.0" ixz="0.0"
                iyy="0.017189" iyz="0.0"
                izz="0.030628"/>
        </inertial>
    </link>
    
    <joint name="right_mid_wheel_to_base_link" type="continuous">
        <origin rpy="0 0 0" xyz="0 -0.27 -0.0508"/>
        <parent link="base_link"/>
        <child link="right_mid_wheel"/>
        <axis xyz="0 1 0"/>
    </joint>    
    
    
<!-- Mast links and joints -->    
    <link name="front_mast_pillar">
        <visual>
            <origin rpy="0 0 0" xyz="0 0 0" />
            <geometry>
                <box size="0.0254 0.0254 1.2954"/>
            </geometry>
        </visual>
        <collision>
            <origin rpy="0 0 0" xyz="0 0 0" />
            <geometry>
                <box size="0.0254 0.0254 1.2954"/>
            </geometry>
        </collision>
        <inertial>
            <origin xyz="0 0 0" rpy="0 0 0"/>
            <mass value="1"/>
            <inertia
                ixx="5.4e-05" ixy="0.0" ixz="0.0"
                iyy="5.4e-05" iyz="0.0"
                izz="0.000108"/>
        </inertial>
    </link>

    <joint name="front_mast_pillar_to_base_link" type="fixed">
        <origin rpy="0 0 0" xyz="0.1833 0 0.7747"/>
        <parent link="base_link"/>
        <child link="front_mast_pillar"/>
    </joint>


    <link name="rear_mast_pillar">
        <visual>
            <origin rpy="0 0 0" xyz="0 0 0" />
            <geometry>
                <box size="0.0254 0.0254 1.2954"/>
            </geometry>
        </visual>
        <collision>
            <origin rpy="0 0 0" xyz="0 0 0" />
            <geometry>
                <box size="0.0254 0.0254 1.2954"/>
            </geometry>
        </collision>
        <inertial>
            <origin xyz="0 0 0" rpy="0 0 0"/>
            <mass value="1"/>
            <inertia
                ixx="5.4e-05" ixy="0.0" ixz="0.0"
                iyy="5.4e-05" iyz="0.0"
                izz="0.000108"/>
        </inertial>
    </link>
    
    <joint name="rear_mast_pillar_to_base_link" type="fixed">
        <origin rpy="0 0 0" xyz="-0.223 0 0.7747"/>
        <parent link="base_link"/>
        <child link="rear_mast_pillar"/>
    </joint>
    
    
    <link name="mid_mast_pillar">
        <visual>
            <origin rpy="0 0 0" xyz="0 0 0" />
            <geometry>
                <box size="0.4064 0.0254 0.0254"/>
            </geometry>
        </visual>
        <collision>
            <origin rpy="0 0 0" xyz="0 0 0" />
            <geometry>
                <box size="0.0254 0.0254 1.2954"/>
            </geometry>
        </collision>
        <inertial>
            <origin xyz="0 0 0" rpy="0 0 0"/>
            <mass value="1"/>
            <inertia
                ixx="5.4e-05" ixy="0.0" ixz="0.0"
                iyy="0.013763" iyz="0.0"
                izz="0.013817"/>
        </inertial>
    </link>
    
    <joint name="mid_mast_pillar_to_base_link" type="fixed">
        <origin rpy="0 0 0" xyz="-0.012 0 0.5461"/>
        <parent link="base_link"/>
        <child link="mid_mast_pillar"/>
    </joint>

    
    <link name="top_mast_pillar">
        <visual>
            <origin rpy="0 0 0" xyz="0 0 0" />
            <geometry>
                <box size="1.016 0.0254 0.0254"/>
            </geometry>
        </visual>
        <collision>
            <origin rpy="0 0 0" xyz="0 0 0" />
            <geometry>
                <box size="1.016 0.0254 0.0254"/>
            </geometry>
        </collision>
        <inertial>
            <origin xyz="0 0 0" rpy="0 0 0"/>
            <mass value="1"/>
            <inertia
                ixx="5.4e-05" ixy="0.0" ixz="0.0"
                iyy="0.086021" iyz="0.0"
                izz="0.086075"/>
        </inertial>
    </link>
    
    <joint name="top_mast_pillar_to_base_link" type="fixed">
        <origin rpy="0 0 0" xyz="-0.012 0 1.4224"/>
        <parent link="base_link"/>
        <child link="top_mast_pillar"/>
    </joint>
    
    
<!-- Lidar Link and joint -->
    <link name="laser_link">
        <visual>
            <origin rpy="0 0 0" xyz="0 0 0" />
            <geometry>
                <cylinder length="0.1524" radius="0.0762"/>
            </geometry>
        </visual>
        <collision>
            <origin rpy="0 0 0" xyz="0 0 0" />
            <geometry>
                <cylinder length="0.1524" radius="0.0762"/>
            </geometry>
        </collision>
        <inertial>
            <origin xyz="0 0 0" rpy="0 0 0"/>
            <mass value="1"/>
            <inertia
                ixx="0.003387" ixy="0.0" ixz="0.0"
                iyy="0.003387" iyz="0.0"
                izz="0.002903"/>
        </inertial>
    </link>
    
    <joint name="laser_to_base_link" type="fixed">
        <origin rpy="0 0 0" xyz="0.2722 0 0.3556"/>
        <parent link="base_link"/>
        <child link="laser_link"/>
    </joint>
    
    
<!-- Imu link, joint, and sensor component -->
    <link name="imu_link">
        <visual>
            <origin rpy="0 0 0" xyz="0 0 0" />
            <geometry>
                <box size="0.0254 0.0254 0.0254"/>
            </geometry>
        </visual>
        <collision>
            <origin rpy="0 0 0" xyz="0 0 0" />
            <geometry>
                <box size="0.0254 0.0254 0.0254"/>
            </geometry>
        </collision>
        <inertial>
            <origin xyz="0 0 0" rpy="0 0 0"/>
            <mass value="1"/>
            <inertia
                ixx="5.4e-05" ixy="0.0" ixz="0.0"
                iyy="5.4e-05" iyz="0.0"
                izz="0.000108"/>
        </inertial>
    </link>
    
    <joint name="imu_link_to_base_link" type="fixed">
        <origin rpy="0 0 0" xyz="-0.012 0 0.5588"/>
        <parent link="base_link"/>
        <child link="imu_link"/>
    </joint>
    
    
<!-- Camera link and joint -->    
    <link name="camera_link">
        <visual>
            <origin rpy="0 0 0" xyz="0 0 0" />
            <geometry>
                <box size="0.1016 0.0508 0.0508"/>
            </geometry>
        </visual>
        <collision>
            <origin rpy="0 0 0" xyz="0 0 0" />
            <geometry>
                <box size="0.0508 0.0508 0.1016"/>
            </geometry>
        </collision>
        <inertial>
            <origin xyz="0 0 0" rpy="0 0 0"/>
            <mass value="0.1"/>
            <inertia
                ixx="0.000215" ixy="0.0" ixz="0.0"
                iyy="0.00086" iyz="0.0"
                izz="0.001075"/>
        </inertial>
    </link>
    
    <joint name="camera_link_to_base_link" type="fixed">
        <origin rpy="0 0.872665 0" xyz="0.3992 0 1.3716"/>
        <parent link="base_link"/>
        <child link="camera_link"/>
    </joint>
     
</robot>
            
